/*Ejemplo de try Catch */

function resta(n1,n2){
    const result = n1 - n3;
    return result;
}

console.log("Inicio del programa");


try {
    resta(1,5); 
} catch (error) {
    console.error("Ocurrio un error, intente mas tarde")
}

console.log('Fin del programa');